Workbook

Sheet Médias 4o Bimestre
A1: RA | B1: Ordem | C1: nome | E1: Exercícios | F1: Projeto | G1: Prova Lab 70% | I1: Prova Teoria 30% | J1: P4
A2: 21.00098-0 | B2: =VLOOKUP(A2,'Ordem Turmas'!A:B,2,FALSE) -> 1 | C2: Izabel Sampaio Goes Pedreira Lapa | D2: =VLOOKUP(A2,'Atividades e Projeto Notas'!A:H,2,FALSE) -> Izabel Sampaio Goes | E2: =VLOOKUP(A2,'Atividades e Projeto Notas'!A:H,7,FALSE) -> 10 | F2: =VLOOKUP(A2,'Atividades e Projeto Notas'!A:H,8,FALSE) -> 10 | G2: =VLOOKUP(A2,'Nota P4 Lab'!C:E,3,FALSE) -> 8 | H2: =VLOOKUP(A2,'Nota P4 Lab'!C:E,2,FALSE) -> Izabel Sampaio Goes | I2: 2 | J2: =MROUND(G2+0.5*I2/6,0.5) -> 8
A3: 19.00386-2 | B3: =VLOOKUP(A3,'Ordem Turmas'!A:B,2,FALSE) -> 2 | C3: Lucas Miguel De Matos Negri | D3: =VLOOKUP(A3,'Atividades e Projeto Notas'!A:H,2,FALSE) -> Lucas Miguel de Matos Negri | E3: =VLOOKUP(A3,'Atividades e Projeto Notas'!A:H,7,FALSE) -> 10 | F3: =VLOOKUP(A3,'Atividades e Projeto Notas'!A:H,8,FALSE) -> 5 | G3: =VLOOKUP(A3,'Nota P4 Lab'!C:E,3,FALSE) -> 7 | H3: =VLOOKUP(A3,'Nota P4 Lab'!C:E,2,FALSE) -> Lucas Miguel de Matos Negri | I3: 2 | J3: =MROUND(G3+0.5*I3/6,0.5) -> 7
A4: 19.02028-7 | B4: =VLOOKUP(A4,'Ordem Turmas'!A:B,2,FALSE) -> 3 | C4: Larissa Navarro Pizarro | D4: =VLOOKUP(A4,'Atividades e Projeto Notas'!A:H,2,FALSE) -> Larissa Navarro Pizarro | E4: =VLOOKUP(A4,'Atividades e Projeto Notas'!A:H,7,FALSE) -> 10 | F4: =VLOOKUP(A4,'Atividades e Projeto Notas'!A:H,8,FALSE) -> 5 | G4: =VLOOKUP(A4,'Nota P4 Lab'!C:E,3,FALSE) -> 3 | H4: =VLOOKUP(A4,'Nota P4 Lab'!C:E,2,FALSE) -> Larissa Navarro Pizarro | I4: 0 | J4: =MROUND(G4+0.5*I4/6,0.5) -> 3
A5: 20.00041-3 | B5: =VLOOKUP(A5,'Ordem Turmas'!A:B,2,FALSE) -> 4 | C5: Bruno Bosa Lopes | D5: =VLOOKUP(A5,'Atividades e Projeto Notas'!A:H,2,FALSE) -> Bruno Bosa Lopes | E5: =VLOOKUP(A5,'Atividades e Projeto Notas'!A:H,7,FALSE) -> 9 | F5: =VLOOKUP(A5,'Atividades e Projeto Notas'!A:H,8,FALSE) -> 10 | G5: =VLOOKUP(A5,'Nota P4 Lab'!C:E,3,FALSE) -> 8 | H5: =VLOOKUP(A5,'Nota P4 Lab'!C:E,2,FALSE) -> Bruno Bosa Lopes | I5: 0 | J5: =MROUND(G5+0.5*I5/6,0.5) -> 8
A6: 20.00601-2 | B6: =VLOOKUP(A6,'Ordem Turmas'!A:B,2,FALSE) -> 5 | C6: Vinicius Urias Da Cruz | D6: =VLOOKUP(A6,'Atividades e Projeto Notas'!A:H,2,FALSE) -> Vinicius Urias da Cruz | E6: =VLOOKUP(A6,'Atividades e Projeto Notas'!A:H,7,FALSE) -> 10 | F6: =VLOOKUP(A6,'Atividades e Projeto Notas'!A:H,8,FALSE) -> 5 | G6: =VLOOKUP(A6,'Nota P4 Lab'!C:E,3,FALSE) -> 5 | H6: =VLOOKUP(A6,'Nota P4 Lab'!C:E,2,FALSE) -> Vinicius Urias da Cruz | I6: 0 | J6: =MROUND(G6+0.5*I6/6,0.5) -> 5
A7: 20.00822-8 | B7: =VLOOKUP(A7,'Ordem Turmas'!A:B,2,FALSE) -> 6 | C7: Gabriel Bianconi | D7: =VLOOKUP(A7,'Atividades e Projeto Notas'!A:H,2,FALSE) -> Gabriel Bianconi | E7: =VLOOKUP(A7,'Atividades e Projeto Notas'!A:H,7,FALSE) -> 9.5 | F7: =VLOOKUP(A7,'Atividades e Projeto Notas'!A:H,8,FALSE) -> 6 | G7: =VLOOKUP(A7,'Nota P4 Lab'!C:E,3,FALSE) -> 7.5 | H7: =VLOOKUP(A7,'Nota P4 Lab'!C:E,2,FALSE) -> Gabriel Bianconi | I7: 1.5 | J7: =MROUND(G7+0.5*I7/6,0.5) -> 7.5
A8: 20.01308-6 | B8: =VLOOKUP(A8,'Ordem Turmas'!A:B,2,FALSE) -> 7 | C8: Carlos Alberto Matias Da Costa | D8: =VLOOKUP(A8,'Atividades e Projeto Notas'!A:H,2,FALSE) -> Carlos Alberto Matias da Costa | E8: =VLOOKUP(A8,'Atividades e Projeto Notas'!A:H,7,FALSE) -> 9.5 | F8: =VLOOKUP(A8,'Atividades e Projeto Notas'!A:H,8,FALSE) -> 6 | G8: =VLOOKUP(A8,'Nota P4 Lab'!C:E,3,FALSE) -> 7 | H8: =VLOOKUP(A8,'Nota P4 Lab'!C:E,2,FALSE) -> Carlos Alberto Matias da Costa | I8: 1 | J8: =MROUND(G8+0.5*I8/6,0.5) -> 7
A9: 20.01629-8 | B9: =VLOOKUP(A9,'Ordem Turmas'!A:B,2,FALSE) -> 8 | C9: Matheus Igino Machado | D9: =VLOOKUP(A9,'Atividades e Projeto Notas'!A:H,2,FALSE) -> Matheus Igino Machado | E9: =VLOOKUP(A9,'Atividades e Projeto Notas'!A:H,7,FALSE) -> 10 | F9: =VLOOKUP(A9,'Atividades e Projeto Notas'!A:H,8,FALSE) -> 5 | G9: =VLOOKUP(A9,'Nota P4 Lab'!C:E,3,FALSE) -> 7 | H9: =VLOOKUP(A9,'Nota P4 Lab'!C:E,2,FALSE) -> Matheus Igino Machado | I9: 2 | J9: =MROUND(G9+0.5*I9/6,0.5) -> 7
A10: 20.01913-0 | B10: =VLOOKUP(A10,'Ordem Turmas'!A:B,2,FALSE) -> 9 | C10: Eduardo Lucas Felippa | D10: =VLOOKUP(A10,'Atividades e Projeto Notas'!A:H,2,FALSE) -> Eduardo Lucas Felippa | E10: =VLOOKUP(A10,'Atividades e Projeto Notas'!A:H,7,FALSE) -> 10 | F10: =VLOOKUP(A10,'Atividades e Projeto Notas'!A:H,8,FALSE) -> 9 | G10: =VLOOKUP(A10,'Nota P4 Lab'!C:E,3,FALSE) -> 8 | H10: =VLOOKUP(A10,'Nota P4 Lab'!C:E,2,FALSE) -> Eduardo Lucas Felippa | I10: 4 | J10: =MROUND(G10+0.5*I10/6,0.5) -> 8.5
A11: 20.02146-0 | B11: =VLOOKUP(A11,'Ordem Turmas'!A:B,2,FALSE) -> 10 | C11: Kaiven Yang Su | D11: =VLOOKUP(A11,'Atividades e Projeto Notas'!A:H,2,FALSE) -> Kaiven Yang Su | E11: =VLOOKUP(A11,'Atividades e Projeto Notas'!A:H,7,FALSE) -> 10 | F11: =VLOOKUP(A11,'Atividades e Projeto Notas'!A:H,8,FALSE) -> 9 | G11: =VLOOKUP(A11,'Nota P4 Lab'!C:E,3,FALSE) -> 7 | H11: =VLOOKUP(A11,'Nota P4 Lab'!C:E,2,FALSE) -> Kaiven Yang Su | I11: 1 | J11: =MROUND(G11+0.5*I11/6,0.5) -> 7
A12: 20.02194-0 | B12: =VLOOKUP(A12,'Ordem Turmas'!A:B,2,FALSE) -> 11 | C12: Bruno Augusto Lopes Fevereiro | D12: =VLOOKUP(A12,'Atividades e Projeto Notas'!A:H,2,FALSE) -> Bruno Augusto Lopes Fevereiro | E12: =VLOOKUP(A12,'Atividades e Projeto Notas'!A:H,7,FALSE) -> 9.5 | F12: =VLOOKUP(A12,'Atividades e Projeto Notas'!A:H,8,FALSE) -> 6 | G12: =VLOOKUP(A12,'Nota P4 Lab'!C:E,3,FALSE) -> 8.5 | H12: =VLOOKUP(A12,'Nota P4 Lab'!C:E,2,FALSE) -> Bruno Augusto Lopes Fevereiro | I12: 2 | J12: =MROUND(G12+0.5*I12/6,0.5) -> 8.5
A13: 21.00127-8 | B13: =VLOOKUP(A13,'Ordem Turmas'!A:B,2,FALSE) -> 12 | C13: Felipe Rodrigues Peixoto Da Silva | D13: =VLOOKUP(A13,'Atividades e Projeto Notas'!A:H,2,FALSE) -> Felipe Rodrigues Peixoto da Silva | E13: =VLOOKUP(A13,'Atividades e Projeto Notas'!A:H,7,FALSE) -> 10 | F13: =VLOOKUP(A13,'Atividades e Projeto Notas'!A:H,8,FALSE) -> 9 | G13: =VLOOKUP(A13,'Nota P4 Lab'!C:E,3,FALSE) -> 8 | H13: =VLOOKUP(A13,'Nota P4 Lab'!C:E,2,FALSE) -> FELIPE RODRIGUES PEIXOTO DA SILVA | I13: 2 | J13: =MROUND(G13+0.5*I13/6,0.5) -> 8
... A40: 21.02093-0 | B40: =VLOOKUP(A40,'Ordem Turmas'!A:B,2,FALSE) -> 39 | C40: Enzo De Britto Suannes Pucci | D40: =VLOOKUP(A40,'Atividades e Projeto Notas'!A:H,2,FALSE) -> Enzo Pucci | E40: =VLOOKUP(A40,'Atividades e Projeto Notas'!A:H,7,FALSE) -> 9 | F40: =VLOOKUP(A40,'Atividades e Projeto Notas'!A:H,8,FALSE) -> 10 | G40: =VLOOKUP(A40,'Nota P4 Lab'!C:E,3,FALSE) -> 5.5 | H40: =VLOOKUP(A40,'Nota P4 Lab'!C:E,2,FALSE) -> Enzo Pucci | I40: 2 | J40: =MROUND(G40+0.5*I40/6,0.5) -> 5.5
C41: Médias | E41: =AVERAGE(E2:E40) -> 9.8333333 | F41: =AVERAGE(F2:F40) -> 8.525641 | J41: =AVERAGE(J2:J40) -> 7.4487179

Sheet Nota P4 Lab
A1: Carimbo de data/hora | B1: Endereço de e-mail | C1: RA | D1: Nome | E1: Nota | F1: Q1. PCA, qual o número de features obtido no modelo? | G1: Q2. Qual o melhor modelo segundo os critérios informados e a acuracidade obtida sobre os dados de teste? | H1: Q3. Qual a classe mais prevista nos novos dados e a sua quantidade? (informe mais de uma classe no caso de empate das quantidades) | I1: Q4. Qual a acuracidade de clusterização obtida? | J1: Q5. Qual o valor de silhueta e melhor número de clusters obtidos? (não se esqueça de fazer os gráfico dos sinais médios de cada grupo no seu notebook) | K1: Poste aqui o link do seu notebook Colab compartilhado como público. Exemplo: https://colab.research.google.com/drive/1cJJWfFTIJ_iWYw7t1VPlPOFBsv9XsCWF#scrollTo=edfpleAbtOzo | L1: Ex1 1a parte | M1: Ex1 2a parte | N1: Ex1 Comentários | O1: Ex2 | P1: Ex2 Comentários | Q1: Ex3 | R1: Ex3 Comentários
A2: 45980.757 | B2: 21.01922-3@maua.br | C2: 21.01922-3 | D2: André Lucas Gois Soares | E2: =(Form_Responses[[#This Row],[Ex1 1a parte]]+Form_Responses[[#This Row],[Ex1 2a parte]]+Form_Responses[[#This Row],[Ex2]]+Form_Responses[[#This Row],[Ex3]]) -> 7 | F2: 438 | G2: Regressão Logística | H2: talk.politics.misc | I2: 2444 | J2: 0.173 e k=2 | K2: https://colab.research.google.com/drive/1iSuuU97BbSIVThHcSNeeudYAVxexSdJN?usp=sharing | L2: 2 | M2: 2.5 | N2: ver tfidf | O2: 2.5 | P2: era sem pca | Q2: 0
A3: 45980.75 | B3: tomferrite1@gmail.com | C3: 21.00663-6 | D3: Antonio Macedo Ferrite | E3: =(Form_Responses[[#This Row],[Ex1 1a parte]]+Form_Responses[[#This Row],[Ex1 2a parte]]+Form_Responses[[#This Row],[Ex2]]+Form_Responses[[#This Row],[Ex3]]) -> 7.5 | F3: 446 | G3: Naive Bayes 0.857 | H3: talk.politics.guns / comp.os.ms-windows.misc Ambas com 3 | I3: 0.564 | J3: k=2 silhueta=0,253 | K3: https://colab.research.google.com/drive/1_VN2Gi8q1oYHPSH94MtaM1DEWiWpOfb3?usp=sharing | L3: 2.5 | M3: 2.5 | O3: 2.5 | P3: era sem pca | Q3: 0
A4: 45980.765 | B4: 20.02194-0@maua.br | C4: 20.02194-0 | D4: Bruno Augusto Lopes Fevereiro | E4: =(Form_Responses[[#This Row],[Ex1 1a parte]]+Form_Responses[[#This Row],[Ex1 2a parte]]+Form_Responses[[#This Row],[Ex2]]+Form_Responses[[#This Row],[Ex3]]) -> 8.5 | F4: 300 | G4: Logistic Regression (REDUZIDO – PCA/SVD) com acurácia = 0.8399 | H4: talk.politics.guns, comp.os.ms-windows.misc | I4: 3974 | J4: k = 2 clusters, com silhueta = 0.2693 | K4: https://colab.research.google.com/drive/19NdMGw5TcVwOuh75WV3T4C9D6KNp3u4J?usp=sharing | L4: 2.5 | M4: 2.5 | O4: 3 | Q4: 0.5 | R4: série errada, era a transposta
A5: 45980.767 | B5: 20.00041-3@maua.br | C5: 20.00041-3 | D5: Bruno Bosa Lopes | E5: =(Form_Responses[[#This Row],[Ex1 1a parte]]+Form_Responses[[#This Row],[Ex1 2a parte]]+Form_Responses[[#This Row],[Ex2]]+Form_Responses[[#This Row],[Ex3]]) -> 8 | F5: 443 | G5: NaiveBayes (Sem PCA) - 0.768 | H5: talk.politics.misc', 'quantidade': 4 | I5: 379 | J5: melhor n clusters: 2, silhueta: 0.173 | K5: https://colab.research.google.com/drive/1JARPotuWUC99JAwYduOjkq222cNsIXnT?usp=sharing | L5: 2.5 | M5: 2.5 | O5: 2.5 | P5: fit_transform | Q5: 0.5 | R5: série errada, era a transposta
A6: 45980.761 | B6: 21.00931-7@maua.br | C6: 21.00931-7 | D6: Caio Montes Correia | E6: =(Form_Responses[[#This Row],[Ex1 1a parte]]+Form_Responses[[#This Row],[Ex1 2a parte]]+Form_Responses[[#This Row],[Ex2]]+Form_Responses[[#This Row],[Ex3]]) -> 8 | F6: 495 | G6: LogisticRegression; 0.806 | H6: talk.politics.misc: 3 , rec.sport.baseball:3 ; alt.atheism: 3 | I6: 5516 | J6: 0.2693, 2 clusters | K6: https://colab.research.google.com/drive/13fKo-wgEZgS37GK481Bd1vkL5VYM7VZl?usp=sharing | L6: 2.5 | M6: 2.5 | O6: 2.5 | P6: fit_transform | Q6: 0.5 | R6: série errada, era a transposta
A7: 45980.758 | B7: 20.01308-6@maua.br | C7: 20.01308-6 | D7: Carlos Alberto Matias da Costa | E7: =(Form_Responses[[#This Row],[Ex1 1a parte]]+Form_Responses[[#This Row],[Ex1 2a parte]]+Form_Responses[[#This Row],[Ex2]]+Form_Responses[[#This Row],[Ex3]]) -> 7 | F7: 1 | G7: DecisionTree (entropy); acuracidade:0.251559 | H7: comp.os.ms-windows.misc e talk.politics.guns , que ficaram empatadas com 3 ocorrências cada | I7: acuracidade: 0.2076 | J7: silhueta: 0.2693; melhor número de clusters: 2 | K7: https://colab.research.google.com/drive/1ubhjkdDpoYNYyACC4ZUMve5bjvHBzJcI?usp=sharing | L7: 2.5 | M7: 2 | N7: algo errado na RL | O7: 2 | P7: tf_idf precisaria ser reaplicado a todos os dados | Q7: 0.5 | R7: série errada, era a transposta
A8: 45980.756 | B8: 21.00781-0@maua.br | C8: 21.00781-0 | D8: Carlos Augusto Freire Maia de Oliveira | E8: =(Form_Responses[[#This Row],[Ex1 1a parte]]+Form_Responses[[#This Row],[Ex1 2a parte]]+Form_Responses[[#This Row],[Ex2]]+Form_Responses[[#This Row],[Ex3]]) -> 8.5 | F8: 446 | G8: O melhor modelo foi o NaiveBayes_Multinomial, com acurácia de 0.8565 sobre os dados de teste. Esse modelo teve o melhor desempenho sem o uso de PCA. Porém considerando o uso do PCA, o modelo LogReg foi escolhido como o melhor modelo com acurácia de 0.8420, já que a perda de acurácia foi de menos de 10% | H8: As classes "talk.politics.guns" e "comp.os.ms-windows.misc" são as mais previstas com 3 ocorrências cada. | I8: 3352 | J8: k: 2 Valor de silhueta: 0.2693239841894235 | K8: https://colab.research.google.com/drive/1LEEfZy61VYbdvsMGwPJ8e2rZL4at1UU_?usp=sharing | L8: 2.5 | M8: 2.5 | O8: 3 | Q8: 0.5 | R8: série errada, era a transposta
A9: 45980.761 | B9: 21.00478-0@maua.br | C9: 21.00478-0 | D9: Cesar Fukushima Kim Bresciani | E9: =(Form_Responses[[#This Row],[Ex1 1a parte]]+Form_Responses[[#This Row],[Ex1 2a parte]]+Form_Responses[[#This Row],[Ex2]]+Form_Responses[[#This Row],[Ex3]]) -> 8 | F9: 446 | G9: Regressão Logística. 85.81% | H9: talk.politics.guns, comp.os.ms-windows.misc | I9: 0.64 | J9: Melhor valor de silhueta: 0.269. Melhor número de clusters: 2 | K9: https://colab.research.google.com/drive/12ovuI-e04k7nfdWPCs-IoPE6tM5HVvKb?usp=sharing | L9: 2.5 | M9: 2.5 | O9: 2.5 | P9: linear_sum_assignment??? | Q9: 0.5 | R9: série errada, era a transposta
A10: 45980.766 | B10: 20.01913-0@maua.br | C10: 20.01913-0 | D10: Eduardo Lucas Felippa | E10: =(Form_Responses[[#This Row],[Ex1 1a parte]]+Form_Responses[[#This Row],[Ex1 2a parte]]+Form_Responses[[#This Row],[Ex2]]+Form_Responses[[#This Row],[Ex3]]) -> 8 | F10: 454 | G10: O melhor modelo foi o de Regressão Logística com PCA, que teve acuracidade de 0.869797 | H10: É a classe comp.os.ms-windows.misc, prevista 3 vezes | I10: 5555 | J10: Silhueta de 0.2693239841894235 para 2 clusters (melhor número) | K10: https://colab.research.google.com/drive/1EGQw0UGgun9sDdQEx3T1pk2g5AVTK4de?usp=sharing | L10: 2.5 | M10: 2.5 | N10: verificar, sem outputs no notebook | O10: 2.5 | P10: verificar, sem outputs no notebook | Q10: 0.5 | R10: série errada, era a transposta
A11: 45980.764 | B11: enderenzo@gmail.com | C11: 21.01535-0 | D11: Enzo Moura | E11: =(Form_Responses[[#This Row],[Ex1 1a parte]]+Form_Responses[[#This Row],[Ex1 2a parte]]+Form_Responses[[#This Row],[Ex2]]+Form_Responses[[#This Row],[Ex3]]) -> 8.5 | F11: 446 | G11: LogisticRegression(max_iter=1000, random_state=42), Acuracidade nos dados de teste: 0.858 | H11: talk.politics.guns, comp.os.ms-windows.misc, com 3 quantidades cada | I11: 640 | J11: Silhueta: 0.2533, Clusters: 2 | K11: https://colab.research.google.com/drive/17EZnI-Zm3ewvDORaMiBJgPummZjUOK6l?usp=sharing | L11: 2.5 | M11: 2.5 | O11: 3 | Q11: 0.5 | R11: série errada, era a transposta
A12: 45980.765 | B12: enzo.britto.pucci@gmail.com | C12: 21.02093-0 | D12: Enzo Pucci | E12: =(Form_Responses[[#This Row],[Ex1 1a parte]]+Form_Responses[[#This Row],[Ex1 2a parte]]+Form_Responses[[#This Row],[Ex2]]+Form_Responses[[#This Row],[Ex3]]) -> 5.5 | F12: 1 | G12: O melhor modelo, segundo os critérios informados, é o Naive Bayes sem PCA, com acurácia de aproximadamente 85,6% nos dados de teste. | H12: Classes: ['talk.politics.guns', 'comp.os.ms-windows.misc'] Quantidade: 3 | I12: Acurácia da clusterização: ~40% (0.3979) | J12: Melhor número de clusters (k): 2 | Valor da silhueta: 0.2533 | K12: https://colab.research.google.com/drive/1PTMIdHgu9s01UIAl2qlHwyd0wdvfVANw?usp=sharing | L12: 1 | M12: 2.5 | N12: SVD? | O12: 1.5 | P12: label encode, Hungarian algorithm | Q12: 0.5 | R12: série errada, era a transposta
A13: 45980.768 | B13: 21.00210-0@maua.br | C13: 21.00210-0 | D13: Enzo Sakamoto | E13: =(Form_Responses[[#This Row],[Ex1 1a parte]]+Form_Responses[[#This Row],[Ex1 2a parte]]+Form_Responses[[#This Row],[Ex2]]+Form_Responses[[#This Row],[Ex3]]) -> 8 | F13: 446 | G13: LogisticRegression, 0.858 | H13: talk.politics.guns, comp.os.ms-windows.misc | I13: 685 | J13: 0.269, 2 | K13: https://colab.research.google.com/drive/1PrBg19ttB_0w_B14dmJtkTbHo6YOzrN8?usp=sharing | L13: 2.5 | M13: 2.5 | O13: 2.5 | P13: linear_sum_assignment??? | Q13: 0.5 | R13: série errada, era a transposta
A14: 45980.759 | B14: 21.00690-3@maua.br | C14: 21.00690-3 | D14: Erick Eiji Nagao | E14: =(Form_Responses[[#This Row],[Ex1 1a parte]]+Form_Responses[[#This Row],[Ex1 2a parte]]+Form_Responses[[#This Row],[Ex2]]+Form_Responses[[#This Row],[Ex3]]) -> 5.5 | F14: 496 | G14: Regressão Logística (com PCA). A acurácia com PCA (0.8179) foi extremamente próxima da original (0.8202), respeitando o critério de perda menor que 10%. | H14: talk.politics.misc, rec.sport.baseball, alt.atheism / Quantidade: 3 | I14: Acuracidade (Silhouette Score) para k=2: 0.2693 | J14: Melhor número de clusters: 2 Valor de silhueta: 0.2693 | K14: https://colab.research.google.com/drive/1okrjPZvaTOOW4VtedLnbbaCNNoPpJ2mA?usp=sharing | L14: 2.5 | M14: 2.5 | O14: 0 | P14: Faltou atenção à explicação do Ex 2 | Q14: 0.5 | R14: série errada, era a transposta
A15: 45980.77 | B15: frps2003@gmail.com | C15: 21.00127-8 | D15: FELIPE RODRIGUES PEIXOTO DA SILVA | E15: =(Form_Responses[[#This Row],[Ex1 1a parte]]+Form_Responses[[#This Row],[Ex1 2a parte]]+Form_Responses[[#This Row],[Ex2]]+Form_Responses[[#This Row],[Ex3]]) -> 8 | F15: 524 | G15: Modelo: LogReg_PCA Acurácia de teste: 0.7952 (PCA usado) | H15: pred talk.politics.guns 3 Name: count, dtype: int64 | I15: 4011 | J15: Melhor número de clusters: 2 Melhor silhueta: 0.2533 | K15: https://colab.research.google.com/drive/1QsXbrE2Elm_9lKlCvDeXcjiolPF1Awbz?usp=sharing | L15: 2.5 | M15: 2.5 | O15: 2.5 | P15: fit_transform | Q15: 0.5 | R15: série errada, era a transposta
A16: 45980.761 | B16: flaviomurata02@gmail.com | C16: 21.01192-3 | D16: Flavio Murata | E16: =(Form_Responses[[#This Row],[Ex1 1a parte]]+Form_Responses[[#This Row],[Ex1 2a parte]]+Form_Responses[[#This Row],[Ex2]]+Form_Responses[[#This Row],[Ex3]]) -> 7 | F16: 496 | G16: LogisticRegression (com PCA), 0.818 | H16: ['talk.politics.misc', 'rec.sport.baseball', 'alt.atheism'], Quantidade: 3 | I16: 554 | J16: Numero clusters: 2, Silhouette Score: 0.2693 | K16: https://colab.research.google.com/drive/1HJ6woaU0cpmgdrcT6qsdJS0XlcWwJ3VF?usp=sharing | L16: 2.5 | M16: 1.5 | N16: Deveria empregar CV | O16: 2.5 | P16: fit_transform | Q16: 0.5 | R16: série errada, era a transposta
A17: 45980.756 | B17: 20.00822-8@maua.br | C17: 20.00822-8 | D17: Gabriel Bianconi | E17: =(Form_Responses[[#This Row],[Ex1 1a parte]]+Form_Responses[[#This Row],[Ex1 2a parte]]+Form_Responses[[#This Row],[Ex2]]+Form_Responses[[#This Row],[Ex3]]) -> 7.5 | F17: 453 | G17: Logistic Regression, acuracidade com PCA, acuracidade: 0.854470 | H17: talk.politics.guns quantidade = 4 | I17: 6309 | J17: k = 2, silhueta = 0.2545 | K17: https://colab.research.google.com/drive/1A5gi7Os5PfDUCfb6r10DWuzKR2yG9WYq?usp=sharing | L17: 2 | M17: 2.5 | N17: stopwords | O17: 2.5 | P17: fit_transform | Q17: 0.5 | R17: série errada, era a transposta
A18: 45980.764 | B18: 21.01286-5@maua.br | C18: 21.01286-5 | D18: Gabriel Henrique Baca Rado | E18: =(Form_Responses[[#This Row],[Ex1 1a parte]]+Form_Responses[[#This Row],[Ex1 2a parte]]+Form_Responses[[#This Row],[Ex2]]+Form_Responses[[#This Row],[Ex3]]) -> 8 | F18: 446 | G18: Regressão Logística, acuracidade: 0.7581 | H18: talk.politics.misc: 3 ocorrências alt.atheism: 3 ocorrências | I18: 3736 | J18: valor de silhueta: 0.1238; 2 clusters | K18: https://colab.research.google.com/drive/1RWBDCnyFNQ_u2m6PJjZ7Oc5irZ0vizum?usp=sharing | L18: 2.5 | M18: 2.5 | O18: 2.5 | P18: fit_transform | Q18: 0.5 | R18: série errada, era a transposta
A19: 45980.752 | B19: gabriel.allievi10@gmail.com | C19: 21.01350-0 | D19: Gabriel Zendron Allievi | E19: =(Form_Responses[[#This Row],[Ex1 1a parte]]+Form_Responses[[#This Row],[Ex1 2a parte]]+Form_Responses[[#This Row],[Ex2]]+Form_Responses[[#This Row],[Ex3]]) -> 8 | F19: 448 | G19: Modelo de regressão logística, com acuracidade de 0.85 | H19: As classes mais previstas foram comp.os.ms-windows.misc e talk.politics.guns, com 3. | I19: 206 | J19: Melhor valor de silhueta: 0.253; Melhor número: 2 | K19: https://colab.research.google.com/drive/1tC9r32nZ6eS8FYIm3YBGsRmI2NxtLxwc?usp=sharing | L19: 2.5 | M19: 2.5 | O19: 2.5 | P19: sem pca | Q19: 0.5 | R19: série errada, era a transposta
A20: 45980.746 | B20: 21.00834-5@maua.br | C20: 21.00834-5 | D20: Igor Improta | E20: =(Form_Responses[[#This Row],[Ex1 1a parte]]+Form_Responses[[#This Row],[Ex1 2a parte]]+Form_Responses[[#This Row],[Ex2]]+Form_Responses[[#This Row],[Ex3]]) -> 8.5 | F20: 495 | G20: Melhor modelo: MultinomialNB-full (sem PCA) Acurácia no conjunto de teste: 0.8052 (80,52%) Usando PCA: Não | H20: Classes mais previstas (empatadas): talk.politics.misc – 3 previsões rec.sport.baseball – 3 previsões alt.atheism – 3 previsões | I20: Acurácia de clusterização (KMeans): 0.5252 | J20: Melhor número de clusters: 2 Valor da silhueta: 0.2533 | K20: https://colab.research.google.com/drive/1tMpEe1TD29uXUlEvM1rYZy2aDVJYDWzo?usp=sharing | L20: 2.5 | M20: 2.5 | O20: 3 | Q20: 0.5 | R20: série errada, era a transposta
A21: 45980.767 | B21: izabel.sampaio120@gmail.com | C21: 21.00098-0 | D21: Izabel Sampaio Goes | E21: =(Form_Responses[[#This Row],[Ex1 1a parte]]+Form_Responses[[#This Row],[Ex1 2a parte]]+Form_Responses[[#This Row],[Ex2]]+Form_Responses[[#This Row],[Ex3]]) -> 8 | F21: 1024 | G21: Modelo: Regressão Logística Dataset: Reduzido (PCA) Acurácia: 0.8087 | H21: talk.politics.guns e comp.os.ms-windows.misc (3) | I21: Acurácia de Clusterização: 0.4376 | J21: Melhor número de clusters (k): 2 Melhor coeficiente de Silhueta: 0.2533 | K21: https://colab.research.google.com/drive/1MBMegOFreDFyrm4EY2WG1ezb4UCxAd20?usp=sharing | L21: 2.5 | M21: 2.5 | O21: 2.5 | P21: fit_transform | Q21: 0.5 | R21: série errada, era a transposta
A22: 45980.764 | B22: 21.01809-0@maua.br | C22: 21.01809-0 | D22: João Paulo de Souza Rodrigues | E22: =(Form_Responses[[#This Row],[Ex1 1a parte]]+Form_Responses[[#This Row],[Ex1 2a parte]]+Form_Responses[[#This Row],[Ex2]]+Form_Responses[[#This Row],[Ex3]]) -> 8 | F22: 1 | G22: O melhor modelo foi o de regressão logística sem PCA, com acurácia de 0,81 | H22: Classe mais vista foi a talk.politics.guns, vista 3 vezes | I22: 0.207 | J22: Melhor número de clusters foi 2, valor da silhueta igual a 0,269 | K22: https://colab.research.google.com/drive/1Z88I0-mxBXF46q1fr6JqHmuNSDrv1xh6?usp=sharing | L22: 2.5 | M22: 2.5 | O22: 2.5 | P22: fit_transform | Q22: 0.5
A23: 45980.752 | B23: 21.00410-2@maua.br | C23: 21.00410-2 | D23: Joao Pedro Soares dos Santos | E23: =(Form_Responses[[#This Row],[Ex1 1a parte]]+Form_Responses[[#This Row],[Ex1 2a parte]]+Form_Responses[[#This Row],[Ex2]]+Form_Responses[[#This Row],[Ex3]]) -> 7.5 | F23: 453 | G23: Regressão Logística , acurácia : 0.8545 | H23: talk.politics.guns, 4 casos | I23: 4648 | J23: valor de silhueta: 0.2533, melhor número de clusters:2 | K23: https://colab.research.google.com/drive/1nuMcL1yKVlo_jomqMEkboSziJYHcUk0L?usp=sharing | L23: 2 | M23: 2.5 | N23: stopwords | O23: 2.5 | P23: fit_transform | Q23: 0.5 | R23: série errada, era a transposta
A24: 45980.765 | B24: 21.01075-7@maua.br | C24: 21.01075-7 | D24: João Vitor Choueri Branco | E24: =(Form_Responses[[#This Row],[Ex1 1a parte]]+Form_Responses[[#This Row],[Ex1 2a parte]]+Form_Responses[[#This Row],[Ex2]]+Form_Responses[[#This Row],[Ex3]]) -> 6 | F24: 584 | G24: O melhor modelo, de acordo com o critério estabelecido, é a Regressão Logística utilizando os dados reduzidos por PCA, que apresentou acurácia de 0.7447, superior tanto ao modelo sem redução (0.7200) quanto aos demais classificadores avaliados. Além disso, a redução não resultou em perda de desempenho, mas sim em leve melhoria, atendendo integralmente ao critério de selecionar o modelo com PCA com perda inferior a 10%. | H24: Classe: 'talk.politics.misc', Quantidade: 4 | I24: XPTO | J24: XPTO | K24: https://colab.research.google.com/drive/1YYGOlIZ-EufckD7UHHZRY17JVzt1PnEx?usp=sharing | L24: 1.5 | M24: 2.5 | N24: stopwords; tfidf já é normalizado | O24: 2 | P24: stopwords; tfidf já é normalizado | Q24: 0
A25: 45980.756 | B25: juliagalhardi.c@gmail.com | C25: 21.01997-5 | D25: Júlia Galhardi Cerqueira | E25: =(Form_Responses[[#This Row],[Ex1 1a parte]]+Form_Responses[[#This Row],[Ex1 2a parte]]+Form_Responses[[#This Row],[Ex2]]+Form_Responses[[#This Row],[Ex3]]) -> 8 | F25: 1024 | G25: O melhor modelo é de Regressão Logística com dados reduzidos (PCA) | H25: As classes mais previstas (quantidade = 3) foram talk.politics.misc e alt.atheism | I25: Acurácia de Clusterização: 0.4171 | J25: Melhor número de clusters (k): 2 (Silhueta: 0.2533) | K25: https://colab.research.google.com/drive/1vgSjyZbXvQ6WCPGEm68HgEsPl_i9vmir?usp=sharing | L25: 2.5 | M25: 2.5 | O25: 2.5 | P25: fit_transform | Q25: 0.5 | R25: série errada, era a transposta
A26: 45980.764 | B26: 20.02146-0@maua.br | C26: 20.02146-0 | D26: Kaiven Yang Su | E26: =(Form_Responses[[#This Row],[Ex1 1a parte]]+Form_Responses[[#This Row],[Ex1 2a parte]]+Form_Responses[[#This Row],[Ex2]]+Form_Responses[[#This Row],[Ex3]]) -> 7 | F26: 446 | G26: O Melhor modelo é a Regressão Logística pois apresnta a maior acurácia, e sua acurácia com o PCA não foi impactada siginificativamente. (84.20% com PCA vs 84.93% sem PCA) | H26: As classes mais previstas foram talk.politics.guns e comp.os.ms-windows.misc, ambas com 3 predições, entre os novos dados (com PCA) | I26: 0 | J26: silhueta: 0.1975, n_cluster: 3 | K26: https://colab.research.google.com/drive/1pBQS_FGFl1l6WPDHKIdRubZ4UPnXU3U8?usp=sharing | L26: 2.5 | M26: 2.5 | O26: 0 | P26: Faltou atenção à explicação do Ex 2 | Q26: 2
A27: 45980.761 | B27: larissa.navarro.pizarro@gmail.com | C27: 19.02028-7 | D27: Larissa Navarro Pizarro | E27: =(Form_Responses[[#This Row],[Ex1 1a parte]]+Form_Responses[[#This Row],[Ex1 2a parte]]+Form_Responses[[#This Row],[Ex2]]+Form_Responses[[#This Row],[Ex3]]) -> 3 | F27: 582 | G27: LogisticRegression_PCA com acurácia de 0.75 | H27: ['talk.politics.misc', 'alt.atheism'] previstas 3 vezes. | I27: 492 | J27: 0.253 e cluster 2 | K27: https://colab.research.google.com/drive/1VnaySQ7kKx3ApXvl6QkR8Q5ct99tO6o6?usp=sharing | L27: 0 | M27: 2.5 | N27: Código nem executa | O27: 0 | P27: Código nem executa | Q27: 0.5 | R27: série errada, era a transposta
A28: 45980.76 | B28: lucas.matosnegri@hotmail.com | C28: 19.00386-2 | D28: Lucas Miguel de Matos Negri | E28: =(Form_Responses[[#This Row],[Ex1 1a parte]]+Form_Responses[[#This Row],[Ex1 2a parte]]+Form_Responses[[#This Row],[Ex2]]+Form_Responses[[#This Row],[Ex3]]) -> 7 | F28: Número de features: 441 | G28: LogReg - 0.8441 | H28: talk.politics.guns = 3 comp.os.ms-windows.misc = 3 | I28: Acurácia da clusterização (K-means): 0.5641 | J28: Melhor número de clusters: k = 2 (silhouette = 0.2798) | K28: https://colab.research.google.com/drive/1wuk9CQ7LSSH3ilUyw3PR6-RIXmcF3sTT?usp=sharing | L28: 2.5 | M28: 1.5 | N28: Deveria empregar CV | O28: 2.5 | P28: fit_transform | Q28: 0.5 | R28: série errada, era a transposta
A29: 45980.768 | B29: mafepinhogarcia@gmail.com | C29: 21.00256-8 | D29: Maria Fernanda Pinho Garcia | E29: =(Form_Responses[[#This Row],[Ex1 1a parte]]+Form_Responses[[#This Row],[Ex1 2a parte]]+Form_Responses[[#This Row],[Ex2]]+Form_Responses[[#This Row],[Ex3]]) -> 9 | F29: 446 | G29: Regressão Logística, acurácia de 0.858 | H29: talk.politics.guns, comp.os.ms-windows.misc | I29: 685 | J29: Silhouette=0.3662, k=2 | K29: https://colab.research.google.com/drive/1KJiy3mkwOhScOa6OXP6orGEVKxxWuKBL?usp=sharing | L29: 2.5 | M29: 2.5 | O29: 2.5 | P29: fit_transform | Q29: 1.5 | R29: 3 clusters
A30: 45980.761 | B30: mathmachadoo@gmail.com | C30: 20.01629-8 | D30: Matheus Igino Machado | E30: =(Form_Responses[[#This Row],[Ex1 1a parte]]+Form_Responses[[#This Row],[Ex1 2a parte]]+Form_Responses[[#This Row],[Ex2]]+Form_Responses[[#This Row],[Ex3]]) -> 7 | F30: 524 | G30: Melhor Modelo: LogReg Acurácia: 0.7952 | H30: Classe mais prevista: ['talk.politics.guns'] Quantidade: 3 | I30: Acurácia da clusterização: 0.4000 | J30: Melhor número de clusters: 2 Silhueta: 0.2533 | K30: https://colab.research.google.com/drive/1aFhIa18wOrxHThQYmLEMe9N9wRyjgXdH?usp=sharing | L30: 2.5 | M30: 1.5 | N30: Deveria empregar CV | O30: 2.5 | P30: fit_transform | Q30: 0.5 | R30: série errada, era a transposta
A31: 45980.762 | B31: 21.01208-3@maua.br | C31: 21.01208-3 | D31: Nathan Zanoni da Hora | E31: =(Form_Responses[[#This Row],[Ex1 1a parte]]+Form_Responses[[#This Row],[Ex1 2a parte]]+Form_Responses[[#This Row],[Ex2]]+Form_Responses[[#This Row],[Ex3]]) -> 7 | F31: 495 | G31: O melhor modelo é a Regressão Logística, sendo que a acuracidade obtida é de 0.804031 | H31: Classe prevista = talk.politics.misc; Quantidade = 3 Classe prevista = rec.sport.baseball; Quantidade = 3 Classe prevista = alt.atheism; Quantidade = 3 | I31: Acuracidade = 0.33851276359600446 | J31: k=2; valor de silheta = 0.2693 | K31: https://colab.research.google.com/drive/1zsqBoO8CsHVlIsPn0lb6FH5JBu9Iflkq?usp=sharing | L31: 2.5 | M31: 1.5 | N31: Deveria empregar CV | O31: 2.5 | P31: fit_transform | Q31: 0.5 | R31: série errada, era a transposta
A32: 45980.766 | B32: nicmfragnan1@gmail.com | C32: 21.00368-8 | D32: Nicole Martins Fragnan | E32: =(Form_Responses[[#This Row],[Ex1 1a parte]]+Form_Responses[[#This Row],[Ex1 2a parte]]+Form_Responses[[#This Row],[Ex2]]+Form_Responses[[#This Row],[Ex3]]) -> 7 | F32: 446 | G32: Logistic Regression com TF-IDF, Acurácia: 0.8493 | H32: talk.politics.guns e comp.os.ms-windows.misc | I32: 3980 | J32: melhor número de clusters = 2. Valor de silhueta = 0.2533 | K32: https://colab.research.google.com/drive/1KL3345xJ3Y9zGEmSdt9TXP9l6D7fq-aa?usp=sharing | L32: 2.5 | M32: 1.5 | N32: Deveria empregar CV | O32: 2.5 | P32: fit_transform | Q32: 0.5 | R32: série errada, era a transposta
A33: 45980.764 | B33: pedromatumoto@gmail.com | C33: 21.00784-5 | D33: Pedro Henrique de Sousa Matumoto | E33: =(Form_Responses[[#This Row],[Ex1 1a parte]]+Form_Responses[[#This Row],[Ex1 2a parte]]+Form_Responses[[#This Row],[Ex2]]+Form_Responses[[#This Row],[Ex3]]) -> 8 | F33: 446 | G33: (LogisticRegression(max_iter=1000, random_state=42), np.float64(0.758))] | H33: alt.atheism e talk.politics.misc | I33: 414 | J33: 0.148 com 2 clusters | K33: https://colab.research.google.com/drive/1W7EfjsJMgy3WR-VdsAAJcUMRW9rXStsb?usp=sharing | L33: 2.5 | M33: 2.5 | O33: 2.5 | P33: X_train? | Q33: 0.5 | R33: série errada, era a transposta
A34: 45980.758 | B34: pedro.gjmesquita@gmail.com | C34: 21.02028-0 | D34: Pedro Mesquita | E34: =(Form_Responses[[#This Row],[Ex1 1a parte]]+Form_Responses[[#This Row],[Ex1 2a parte]]+Form_Responses[[#This Row],[Ex2]]+Form_Responses[[#This Row],[Ex3]]) -> 7.5 | F34: 3801 | G34: Regressão Logística PCA; 0.858058 | H34: talk.politics.guns 3 comp.os.ms-windows.misc 3 | I34: 6406 | J34: 2; 0.2693 | K34: https://colab.research.google.com/drive/1lyCpjTUuy9JS2FDzara9_fTdc2kS3Ey1?usp=sharing | L34: 2.5 | M34: 1.5 | N34: Deveria empregar CV | O34: 3 | P34: fit_transform, mas compensou ao mostrar a matriz de confusão | Q34: 0.5 | R34: série errada, era a transposta
A35: 45980.769 | B35: 20.00611-0@maua.br | C35: 20.00611-0 | D35: Rafael Rubio | E35: =(Form_Responses[[#This Row],[Ex1 1a parte]]+Form_Responses[[#This Row],[Ex1 2a parte]]+Form_Responses[[#This Row],[Ex2]]+Form_Responses[[#This Row],[Ex3]]) -> 7 | F35: 446 | G35: LogisticRegression 0.849 sem PCA | I35: 397 | J35: silhueta = 0.269 k = 2 | K35: https://colab.research.google.com/drive/16NJraowRZMTHXQcUjuEeP867wJldFUZG?usp=sharing | L35: 2.5 | M35: 1.5 | N35: Predição de novos casos? | O35: 2.5 | P35: linear_sum_assignment??? | Q35: 0.5 | R35: série errada, era a transposta
A36: 45980.755 | B36: raphaelfr01@gmail.com | C36: 21.00334-3 | D36: Raphael Fernandes Raymundo | E36: =(Form_Responses[[#This Row],[Ex1 1a parte]]+Form_Responses[[#This Row],[Ex1 2a parte]]+Form_Responses[[#This Row],[Ex2]]+Form_Responses[[#This Row],[Ex3]]) -> 7.5 | F36: 495 | G36: LogisticRegression | H36: talk.politics.misc, rec.sport.baseball, alt.atheism | I36: 464 | J36: k=2 e silhueta = 0.269 | K36: https://colab.research.google.com/drive/1Fw1RZ0C_-6H6vsmCBZLdmWWaJnvQAIlw?usp=sharing | L36: 2.5 | M36: 1.5 | N36: Deveria empregar CV | O36: 3 | Q36: 0.5 | R36: série errada, era a transposta
A37: 45980.763 | B37: Ryuske2009@hotmail.com | C37: 21.00745-4 | D37: Ryuske Hideaki Sato | E37: =(Form_Responses[[#This Row],[Ex1 1a parte]]+Form_Responses[[#This Row],[Ex1 2a parte]]+Form_Responses[[#This Row],[Ex2]]+Form_Responses[[#This Row],[Ex3]]) -> 7.5 | F37: 446 | G37: Logistic Regression PCA com acuracidade de 0.8581 | H37: Teve empate entre a classe talk.politics.guns e comp.os.ms-windows.misc os dois com 3 | I37: 6868 | J37: 0.2533 de silhueta com 2 clusters | K37: https://colab.research.google.com/drive/16W1DQL9M041BTjPg2S0d4stAdw2Q-Bir?usp=sharing | L37: 2.5 | M37: 2 | N37: Predição de novos casos? Estranha | O37: 2.5 | P37: fit_transform, mas compensou ao mostrar a matriz de confusão | Q37: 0.5 | R37: série errada, era a transposta
A38: 45980.758 | B38: vinicius.berti33@gmail.com | C38: 21.01219-9 | D38: Vinícius de Oliveira Berti | E38: =(Form_Responses[[#This Row],[Ex1 1a parte]]+Form_Responses[[#This Row],[Ex1 2a parte]]+Form_Responses[[#This Row],[Ex2]]+Form_Responses[[#This Row],[Ex3]]) -> 7 | F38: 496 | G38: LogisticRegression:0.817869 | H38: Classe: talk.politics.misc, Quantidade: 3 Classe: rec.sport.baseball, Quantidade: 3 Classe: alt.atheism, Quantidade: 3 | I38: 5621 | J38: Melhor número de clusters: k=2, Valor de silhueta: 0.2533 | K38: https://github.com/ViniciusBerti/20241_maua_ecm252_intro_git/blob/main/IMT_P4_2025.ipynb | L38: 2.5 | M38: 1.5 | N38: Task???; Deveria empregar CV | O38: 2.5 | P38: fit_transform | Q38: 0.5 | R38: série errada, era a transposta
A39: 45980.755 | B39: vinicius.urias@gmail.com | C39: 20.00601-2 | D39: Vinicius Urias da Cruz | E39: =(Form_Responses[[#This Row],[Ex1 1a parte]]+Form_Responses[[#This Row],[Ex1 2a parte]]+Form_Responses[[#This Row],[Ex2]]+Form_Responses[[#This Row],[Ex3]]) -> 5 | F39: 446 | G39: Regressão Logística | H39: talk.politics.guns: 4 | I39: 4.0045389e+15 | J39: sil: 0.2693239841894235; n_clusters: 2 | K39: https://colab.research.google.com/drive/1MCognV-AgQdpvUD9uqJdyxkgrS0QJ1Pz?usp=sharing | L39: 1 | M39: 2.5 | N39: SVD? | O39: 1 | P39: Cálculo errado | Q39: 0.5 | R39: série errada, era a transposta
A40: 45980.76 | B40: 21.01444-2@maua.br | C40: 21.01444-2 | D40: Vitor Soller | E40: =(Form_Responses[[#This Row],[Ex1 1a parte]]+Form_Responses[[#This Row],[Ex1 2a parte]]+Form_Responses[[#This Row],[Ex2]]+Form_Responses[[#This Row],[Ex3]]) -> 8 | F40: 446 | G40: LogisticRegression com PCA - 0.842 | H40: talk.politics.guns 3 comp.os.ms-windows.misc 3 | I40: 398 | J40: 0.267, 2 | K40: https://colab.research.google.com/drive/1l4oF6hnmB3fJzABZCNyaquRN_DDQpcPd?usp=sharing | L40: 2.5 | M40: 2.5 | O40: 2.5 | P40: fit_transform | Q40: 0.5 | R40: série errada, era a transposta

Sheet Atividades e Projeto Notas
A1: RA | B1: Nome | C1: Nome | D1: Grupo | E1: Nota Ex 4.1 | F1: Nota Ex 4.2 | G1: Ex 4 | H1: Projeto 2
A2: 21.01922-3 | B2: André Soares | C2: Andre Lucas Gois Soares | D2: 10 | E2: =VLOOKUP(A2,'Atividades e Projeto Comentario'!A:L,5,FALSE) -> 9 | F2: =VLOOKUP(A2,'Atividades e Projeto Comentario'!A:L,9,FALSE) -> 9 | G2: =MIN((E2+F2)/2,10) -> 9 | H2: =VLOOKUP(A2,'Atividades e Projeto Comentario'!A:L,12,FALSE) -> 10
A3: 21.00663-6 | B3: Antonio Macedo Ferrite | C3: Antonio Macedo Ferrite | D3: 7 | E3: =VLOOKUP(A3,'Atividades e Projeto Comentario'!A:L,5,FALSE) -> 12 | F3: =VLOOKUP(A3,'Atividades e Projeto Comentario'!A:L,9,FALSE) -> 9 | G3: =MIN((E3+F3)/2,10) -> 10 | H3: =VLOOKUP(A3,'Atividades e Projeto Comentario'!A:L,12,FALSE) -> 9.5
A4: 20.02194-0 | B4: Bruno Augusto Lopes Fevereiro | C4: Bruno Augusto Lopes Fevereiro | D4: 6 | E4: =VLOOKUP(A4,'Atividades e Projeto Comentario'!A:L,5,FALSE) -> 10 | F4: =VLOOKUP(A4,'Atividades e Projeto Comentario'!A:L,9,FALSE) -> 9 | G4: =MIN((E4+F4)/2,10) -> 9.5 | H4: =VLOOKUP(A4,'Atividades e Projeto Comentario'!A:L,12,FALSE) -> 6
A5: 20.00041-3 | B5: Bruno Bosa Lopes | C5: Bruno Bosa Lopes | D5: 10 | E5: =VLOOKUP(A5,'Atividades e Projeto Comentario'!A:L,5,FALSE) -> 9 | F5: =VLOOKUP(A5,'Atividades e Projeto Comentario'!A:L,9,FALSE) -> 9 | G5: =MIN((E5+F5)/2,10) -> 9 | H5: =VLOOKUP(A5,'Atividades e Projeto Comentario'!A:L,12,FALSE) -> 10
A6: 21.00931-7 | B6: Caio Montes Correia | C6: Caio Montes Correia | D6: 10 | E6: =VLOOKUP(A6,'Atividades e Projeto Comentario'!A:L,5,FALSE) -> 9 | F6: =VLOOKUP(A6,'Atividades e Projeto Comentario'!A:L,9,FALSE) -> 9 | G6: =MIN((E6+F6)/2,10) -> 9 | H6: =VLOOKUP(A6,'Atividades e Projeto Comentario'!A:L,12,FALSE) -> 10
A7: 20.01308-6 | B7: Carlos Alberto Matias da Costa | C7: Carlos Alberto Matias da Costa | D7: 6 | E7: =VLOOKUP(A7,'Atividades e Projeto Comentario'!A:L,5,FALSE) -> 10 | F7: =VLOOKUP(A7,'Atividades e Projeto Comentario'!A:L,9,FALSE) -> 9 | G7: =MIN((E7+F7)/2,10) -> 9.5 | H7: =VLOOKUP(A7,'Atividades e Projeto Comentario'!A:L,12,FALSE) -> 6
A8: 21.00781-0 | B8: Carlos Augusto Freire Maia de Oliveira | C8: Carlos Augusto Freire Maia de Oliveira | D8: 9 | E8: =VLOOKUP(A8,'Atividades e Projeto Comentario'!A:L,5,FALSE) -> 11 | F8: =VLOOKUP(A8,'Atividades e Projeto Comentario'!A:L,9,FALSE) -> 9 | G8: =MIN((E8+F8)/2,10) -> 10 | H8: =VLOOKUP(A8,'Atividades e Projeto Comentario'!A:L,12,FALSE) -> 9.5
A9: 21.00478-0 | B9: Cesar Fukushima Kim Bresciani | C9: Cesar Fukushima Kim Bresciani | D9: 9 | E9: =VLOOKUP(A9,'Atividades e Projeto Comentario'!A:L,5,FALSE) -> 11 | F9: =VLOOKUP(A9,'Atividades e Projeto Comentario'!A:L,9,FALSE) -> 9 | G9: =MIN((E9+F9)/2,10) -> 10 | H9: =VLOOKUP(A9,'Atividades e Projeto Comentario'!A:L,12,FALSE) -> 9.5
A10: 20.01913-0 | B10: Eduardo Lucas Felippa | C10: Eduardo Lucas Felippa | D10: 8 | E10: =VLOOKUP(A10,'Atividades e Projeto Comentario'!A:L,5,FALSE) -> 11 | F10: =VLOOKUP(A10,'Atividades e Projeto Comentario'!A:L,9,FALSE) -> 9 | G10: =MIN((E10+F10)/2,10) -> 10 | H10: =VLOOKUP(A10,'Atividades e Projeto Comentario'!A:L,12,FALSE) -> 9
A11: 21.01535-0 | B11: Enzo Moura | C11: Enzo Leonardo Sabatelli de Moura | D11: 9 | E11: =VLOOKUP(A11,'Atividades e Projeto Comentario'!A:L,5,FALSE) -> 11 | F11: =VLOOKUP(A11,'Atividades e Projeto Comentario'!A:L,9,FALSE) -> 9 | G11: =MIN((E11+F11)/2,10) -> 10 | H11: =VLOOKUP(A11,'Atividades e Projeto Comentario'!A:L,12,FALSE) -> 9.5
A12: 21.02093-0 | B12: Enzo Pucci | C12: Enzo Suannes Pucci | D12: 10 | E12: =VLOOKUP(A12,'Atividades e Projeto Comentario'!A:L,5,FALSE) -> 9 | F12: =VLOOKUP(A12,'Atividades e Projeto Comentario'!A:L,9,FALSE) -> 9 | G12: =MIN((E12+F12)/2,10) -> 9 | H12: =VLOOKUP(A12,'Atividades e Projeto Comentario'!A:L,12,FALSE) -> 10
A13: 21.00210-0 | B13: Enzo Sakamoto | C13: Enzo Sakamoto | D13: 3 | E13: =VLOOKUP(A13,'Atividades e Projeto Comentario'!A:L,5,FALSE) -> 12 | F13: =VLOOKUP(A13,'Atividades e Projeto Comentario'!A:L,9,FALSE) -> 10 | G13: =MIN((E13+F13)/2,10) -> 10 | H13: =VLOOKUP(A13,'Atividades e Projeto Comentario'!A:L,12,FALSE) -> 10
... A40: 21.01444-2 | B40: Vitor Guirão Soller | C40: Vitor Soller | D40: 3 | E40: =VLOOKUP(A40,'Atividades e Projeto Comentario'!A:L,5,FALSE) -> 12 | F40: =VLOOKUP(A40,'Atividades e Projeto Comentario'!A:L,9,FALSE) -> 10 | G40: =MIN((E40+F40)/2,10) -> 10 | H40: =VLOOKUP(A40,'Atividades e Projeto Comentario'!A:L,12,FALSE) -> 10

Sheet Atividades e Projeto Comentario
A1: RA | B1: Nome | C1: Nome | D1: Grupo | E1: Nota Ex 4.1 | F1: Comentários Ex 4.1 | G1: Modelo 1 | H1: Modelo 2 | I1: Nota Ex 4.2 | J1: Comentários Ex 4.2 | K1: Ex 4 | L1: Projeto 2 | M1: Comentários Projeto 2
A2: 21.00098-0 | B2: Izabel Sampaio Goes | C2: Izabel Sampaio Goes | D2: 1 | E2: 12 | F2: Excelente! | G2: lucas-leme/FinBERT-PT-BR | H2: SentiLex-PT | I2: 9 | J2: Adjusted Rand Index (ARI), não foi a comparação pedida... | K2: =MIN((E2+I2)/2,10) -> 10 | L2: 10 | M2: A ausência do vídeo na apresentação não teve impacto; apresentação foi muito boa, e vi o vídeo depois; Fizeram seleção de vários modelos; SHAP; curva ROC; (Optuna + Weights & Bias); Técnicas de data augumentation, SHAP, excelente! O problema dos tamanhos diferentes nas avaliações, acaba sendo um problema menor. A aplicação excelente, como também o artigo.
A3: 21.01997-5 | B3: Júlia Galhardi Cerqueira | C3: Júlia Galhardi Cerqueira | D3: 1 | E3: 12 | F3: Excelente! | G3: lucas-leme/FinBERT-PT-BR | H3: SentiLex-PT | I3: 9 | J3: Adjusted Rand Index (ARI), não foi a comparação pedida... | K3: =MIN((E3+I3)/2,10) -> 10 | L3: 10
A4: 21.00690-3 | B4: Erick Eiji Nagao | C4: ERICK EIJI NAGAO | D4: 2 | E4: 11 | F4: Análises bastante superficiais | G4: neuralmind/bert-base-portuguese-cased | H4: TextBlob: Simplified Text Processing | I4: 9 | J4: A matriz de confusão precisava ser ajustada em todos os casos | K4: =MIN((E4+I4)/2,10) -> 10 | L4: 9 | M4: Apresentação média... Não localizei no GitHub, mas achei o vídeo. Poderiam ter falado o toxi-Bert, llimitações do modelo, falando mais da relevância e cenários de uso. Teriam muito o que explorar aqui. Aplicação simples, mas atende. Conjunto de dados de treinamento um pouco limitado, e a classificação... mas para um trabalho escolar, ok. Faltou um comparativo/métrica para entendermos o quanto funciona. Também não localizei no GitHub o artigo, que era um dos entregáveis do projeto.
A5: 21.01286-5 | B5: Gabriel Henrique Baca Rado | C5: GABRIEL HENRIQUE BACA RADO | D5: 2 | E5: 11 | F5: Análises bastante superficiais | G5: neuralmind/bert-base-portuguese-cased | H5: TextBlob: Simplified Text Processing | I5: 9 | J5: Adjusted Rand Index (ARI), não foi a comparação pedida... | K5: =MIN((E5+I5)/2,10) -> 10 | L5: 9
A6: 21.00834-5 | B6: Igor Improta | C6: IGOR IMPROTA MARTINEZ DA SILVA | D6: 2 | E6: 11 | F6: Análises bastante superficiais | G6: neuralmind/bert-base-portuguese-cased | H6: TextBlob: Simplified Text Processing | I6: 9 | J6: Adjusted Rand Index (ARI), não foi a comparação pedida... | K6: =MIN((E6+I6)/2,10) -> 10 | L6: 9
A7: 21.00745-4 | B7: Ryuske Hideaki Sato | C7: RYUSKE HIDEAKI SATO | D7: 2 | E7: 11 | F7: Análises bastante superficiais | G7: neuralmind/bert-base-portuguese-cased | H7: TextBlob: Simplified Text Processing | I7: 9 | J7: Adjusted Rand Index (ARI), não foi a comparação pedida... | K7: =MIN((E7+I7)/2,10) -> 10 | L7: 9
A8: 21.01219-9 | B8: Vinícius de Oliveira Berti | C8: VINICIUS DE OLIVEIRA BERTI | D8: 2 | E8: 11 | F8: Análises bastante superficiais | G8: neuralmind/bert-base-portuguese-cased | H8: TextBlob: Simplified Text Processing | I8: 9 | J8: Adjusted Rand Index (ARI), não foi a comparação pedida... | K8: =MIN((E8+I8)/2,10) -> 10 | L8: 9
A9: 21.00210-0 | B9: Enzo Sakamoto | C9: Enzo Sakamoto | D9: 3 | E9: 12 | F9: Análise da escolha do modelo superficial, mas excelente terem empregado o SARIMAX o que compensou | G9: nlptown/bert-base-multilingual-uncased-sentiment | H9: TextBlob: Simplified Text Processing | I9: 10 | J9: Deviam ser seguido com a matriz de confusão inicial e não o ARI | K9: =MIN((E9+I9)/2,10) -> 10 | L9: 10 | M9: Apresentação muito boa, um tema relevante e aplicação ok. sem fine-tunnig, mas avaliado...
A10: 21.01075-7 | B10: João Vitor Choueri Branco | C10: João Branco | D10: 3 | E10: 12 | F10: Análise da escolha do modelo superficial, mas excelente terem empregado o SARIMAX o que compensou | G10: nlptown/bert-base-multilingual-uncased-sentiment | H10: TextBlob: Simplified Text Processing | I10: 10 | J10: Deviam ser seguido com a matriz de confusão inicial e não o ARI | K10: =MIN((E10+I10)/2,10) -> 10 | L10: 10
A11: 21.00784-5 | B11: Pedro Henrique de Sousa Matumoto | C11: Pedro Matumoto | D11: 3 | E11: 12 | F11: Análise da escolha do modelo superficial, mas excelente terem empregado o SARIMAX o que compensou | G11: nlptown/bert-base-multilingual-uncased-sentiment | H11: TextBlob: Simplified Text Processing | I11: 10 | J11: Adjusted Rand Index (ARI), não foi a comparação pedida... | K11: =MIN((E11+I11)/2,10) -> 10 | L11: 10
A12: 20.00611-0 | B12: Rafael Rubio | C12: Rafael Rubio | D12: 3 | E12: 12 | F12: Análise da escolha do modelo superficial, mas excelente terem empregado o SARIMAX o que compensou | G12: nlptown/bert-base-multilingual-uncased-sentiment | H12: TextBlob: Simplified Text Processing | I12: 10 | J12: Adjusted Rand Index (ARI), não foi a comparação pedida... | K12: =MIN((E12+I12)/2,10) -> 10 | L12: 10
A13: 21.01444-2 | B13: Vitor Guirão Soller | C13: Vitor Soller | D13: 3 | E13: 12 | F13: Análise da escolha do modelo superficial, mas excelente terem empregado o SARIMAX o que compensou | G13: nlptown/bert-base-multilingual-uncased-sentiment | H13: TextBlob: Simplified Text Processing | I13: 10 | J13: Adjusted Rand Index (ARI), não foi a comparação pedida... | K13: =MIN((E13+I13)/2,10) -> 10 | L13: 10
A14: 21.01350-0 | B14: Gabriel Zendron Allievi | C14: Gabriel Zendron Alliev | D14: 4 | E14: 11 | F14: Análises bastante superficiais, não seria melhor empregarem métricas no lugar de 'observa-se' | G14: lucas-leme/FinBERT-PT-BR | H14: from nltk.sentiment.vader import SentimentIntensityAnalyzer | I14: 9 | J14: Adjusted Rand Index (ARI), não foi a comparação pedida... | K14: =MIN((E14+I14)/2,10) -> 10 | L14: 7 | M14: Apresentação centrada apenas no Código, sem dar qualquer relevância ao tema ou ao caso de uso, API key para 1000, duzentas de cada genêro... Não faz muito sentido uma distribuição equitativa só para facilitar. Poderiam ter traduzido os resumos com qualquer IA. Aplicação e problemas bastante simples, e como falamos antes, seria então necessário explorar de forma mais aprofundada/rigorosa. Acurácia e F1, sem explicar muito... Artigo, demasiadamente resumido e referências protocolares.
A15: 21.01809-0 | B15: João Paulo de Souza Rodrigues | C15: João Paulo de Souza Rodrigues | D15: 4 | E15: 11 | F15: Análises bastante superficiais, não seria melhor empregarem métricas no lugar de 'observa-se' | G15: lucas-leme/FinBERT-PT-BR | H15: from nltk.sentiment.vader import SentimentIntensityAnalyzer | I15: 9 | J15: Deviam ser seguido com a matriz de confusão inicial e não o ARI | K15: =MIN((E15+I15)/2,10) -> 10 | L15: 7
A16: 21.00410-2 | B16: João Pedro Soares dos Santos | C16: João Pedro Soares dos Santos | D16: 4 | E16: 11 | F16: Análises bastante superficiais, não seria melhor empregarem métricas no lugar de 'observa-se' | G16: lucas-leme/FinBERT-PT-BR | H16: from nltk.sentiment.vader import SentimentIntensityAnalyzer | I16: 9 | J16: Deviam ser seguido com a matriz de confusão inicial e não o ARI | K16: =MIN((E16+I16)/2,10) -> 10 | L16: 7
A17: 21.01208-3 | B17: Nathan Zanoni | C17: Nathan Zanoni Da Hora | D17: 4 | E17: 11 | F17: Análises bastante superficiais, não seria melhor empregarem métricas no lugar de 'observa-se' | G17: lucas-leme/FinBERT-PT-BR | H17: from nltk.sentiment.vader import SentimentIntensityAnalyzer | I17: 9 | J17: Adjusted Rand Index (ARI), não foi a comparação pedida... | K17: =MIN((E17+I17)/2,10) -> 10 | L17: 7
A18: 19.02028-7 | B18: Larissa Navarro Pizarro | C18: Larissa Navarro Pizarro | D18: 5 | E18: 11 | F18: Análises bastante superficiais | G18: nlptown/bert-base-multilingual-uncased-sentiment | H18: LeIA import SentimentIntensityAnalyzer | I18: 9 | J18: Adjusted Rand Index (ARI), não foi a comparação pedida... | K18: =MIN((E18+I18)/2,10) -> 10 | L18: 5 | M18: O trabalho, focou em uma análise de sentimentos, que não era nenhum dos temas do trabalho, ficando assim fora da possibilidade de uma avaliação. Isso foi apontado antes nas propostas e deveria ter sido tratado.
A19: 19.00386-2 | B19: Lucas Miguel de Matos Negri | C19: Lucas Miguel de Matos Negri | D19: 5 | E19: 11 | F19: Análises bastante superficiais | G19: nlptown/bert-base-multilingual-uncased-sentiment | H19: LeIA import SentimentIntensityAnalyzer | I19: 9 | J19: Adjusted Rand Index (ARI), não foi a comparação pedida... | K19: =MIN((E19+I19)/2,10) -> 10 | L19: 5
A20: 20.01629-8 | B20: Matheus Igino Machado | C20: Matheus Igino Machado | D20: 5 | E20: 11 | F20: Análises bastante superficiais | G20: nlptown/bert-base-multilingual-uncased-sentiment | H20: LeIA import SentimentIntensityAnalyzer | I20: 9 | J20: Adjusted Rand Index (ARI), não foi a comparação pedida... | K20: =MIN((E20+I20)/2,10) -> 10 | L20: 5
A21: 20.00601-2 | B21: Vinicius Urias da Cruz | C21: Vinicius Urias Da Cruz | D21: 5 | E21: 11 | F21: Análises bastante superficiais | G21: nlptown/bert-base-multilingual-uncased-sentiment | H21: LeIA import SentimentIntensityAnalyzer | I21: 9 | J21: Adjusted Rand Index (ARI), não foi a comparação pedida... | K21: =MIN((E21+I21)/2,10) -> 10 | L21: 5
A22: 20.02194-0 | B22: Bruno Augusto Lopes Fevereiro | C22: Bruno Augusto Lopes Fevereiro | D22: 6 | E22: 10 | F22: Análises bastante superficiais | G22: nlptown/bert-base-multilingual-uncased-sentiment | H22: LeIA import SentimentIntensityAnalyzer | I22: 9 | J22: Adjusted Rand Index (ARI), não foi a comparação pedida... | K22: =MIN((E22+I22)/2,10) -> 9.5 | L22: 6 | M22: Mascaram um problema de regressao em problema de classificação. Acho que alertei para esse problema antes de seguirem com essa entrega. Métricas e metodologia de treinamento que foram aplicadas estão inadequadadas. O artigo, foi protocolar, de fato não atende. Ficou bastante incompleto. Para um projeto, tivemos exercícios que exigiram mais, não acham?
A23: 20.01308-6 | B23: Carlos Alberto Matias da Costa | C23: Carlos Alberto Matias da Costa | D23: 6 | E23: 10 | F23: Análises bastante superficiais | G23: nlptown/bert-base-multilingual-uncased-sentiment | H23: LeIA import SentimentIntensityAnalyzer | I23: 9 | J23: Adjusted Rand Index (ARI), não foi a comparação pedida... | K23: =MIN((E23+I23)/2,10) -> 9.5 | L23: 6
A24: 20.00822-8 | B24: Gabriel Bianconi | C24: Gabriel Bianconi | D24: 6 | E24: 10 | F24: Análises bastante superficiais | G24: nlptown/bert-base-multilingual-uncased-sentiment | H24: LeIA import SentimentIntensityAnalyzer | I24: 9 | J24: A matriz de confusão precisava ser ajustada em todos os casos | K24: =MIN((E24+I24)/2,10) -> 9.5 | L24: 6
A25: 21.00663-6 | B25: Antonio Macedo Ferrite | C25: Antonio Macedo Ferrite | D25: 7 | E25: 12 | F25: Excelente! | G25: !ollama pull mistral | H25: NLTK - Natural Language Toolkit | I25: 9 | J25: Adjusted Rand Index (ARI), não foi a comparação pedida... | K25: =MIN((E25+I25)/2,10) -> 10 | L25: 9.5 | M25: Apresentação muit boa (exceção à parte da história de dificuldade/problema/5GB, o que é desnessário neste tipo de apresentação). Excelente, terem empregado testes estatísticos para medir a eficácia dos remédios. O resultados não foram tão bons, XGBClassifier, 54% acurácia... mas era um projeto desafiador e no tempo que tiveram fizeram bastante progresso. O GitHub deixou um pouco a desejar pela simplicidade e por colocar os artefatos fora (notion etc.). O artigo, simples, mas ok.
A26: 21.00256-8 | B26: Maria Fernanda Pinho Garcia | C26: Maria Fernanda Pinho Garcia | D26: 7 | E26: 12 | F26: Excelente! | G26: !ollama pull mistral | H26: NLTK - Natural Language Toolkit | I26: 9 | J26: Adjusted Rand Index (ARI), não foi a comparação pedida... | K26: =MIN((E26+I26)/2,10) -> 10 | L26: 9.5
A27: 20.01913-0 | B27: Eduardo Lucas Felippa | C27: Eduardo Lucas Felippa | D27: 8 | E27: 11 | F27: Análises um pouco confusas e superficiais | G27: lipaoMai/sentiment-model-portuguese-distilbert-pos-neg | H27: TextBlob: Simplified Text Processing | I27: 9 | J27: Deviam ser seguido com a matriz de confusão inicial e não o ARI | K27: =MIN((E27+I27)/2,10) -> 10 | L27: 9 | M27: Cold start, Apresentação muito boa, 42K dados, baixo, médio, luxo... Não foi muito bom... LIME e SHAP, resultados muito bons na parte da explicabilidade. Aplicação muito boa... Gráfica etc. Não encontrei o "artigo" no GitHub, talvez tenham confundido com o readme, mas seriam coisas diferentes.
A28: 21.00127-8 | B28: Felipe Rodrigues Peixoto da Silva | C28: Felipe Rodrigues Peixoto da Silva | D28: 8 | E28: 11 | F28: Análises um pouco confusas e superficiais | G28: lipaoMai/sentiment-model-portuguese-distilbert-pos-neg | H28: TextBlob: Simplified Text Processing | I28: 9 | J28: A matriz de confusão precisava ser ajustada em todos os casos | K28: =MIN((E28+I28)/2,10) -> 10 | L28: 9
A29: 21.01192-3 | B29: Flavio Murata | C29: Flávio Murata | D29: 8 | E29: 11 | F29: Análises um pouco confusas e superficiais | G29: lipaoMai/sentiment-model-portuguese-distilbert-pos-neg | H29: TextBlob: Simplified Text Processing | I29: 9 | J29: A matriz de confusão precisava ser ajustada em todos os casos | K29: =MIN((E29+I29)/2,10) -> 10 | L29: 9
A30: 20.02146-0 | B30: Kaiven Yang Su | C30: Kaiven Yang Su | D30: 8 | E30: 11 | F30: Análises um pouco confusas e superficiais | G30: lipaoMai/sentiment-model-portuguese-distilbert-pos-neg | H30: TextBlob: Simplified Text Processing | I30: 9 | J30: Adjusted Rand Index (ARI), não foi a comparação pedida... | K30: =MIN((E30+I30)/2,10) -> 10 | L30: 9
A31: 21.00368-8 | B31: Nicole Martins Fragnan | C31: Nicole Martins Fragnan | D31: 8 | E31: 11 | F31: Análises um pouco confusas e superficiais | G31: lipaoMai/sentiment-model-portuguese-distilbert-pos-neg | H31: TextBlob: Simplified Text Processing | I31: 9 | J31: Adjusted Rand Index (ARI), não foi a comparação pedida... | K31: =MIN((E31+I31)/2,10) -> 10 | L31: 9
A32: 21.00334-3 | B32: Raphael Fernandes Raymundo | C32: Raphael Raymundo | D32: 8 | E32: 11 | F32: Análises um pouco confusas e superficiais | G32: lipaoMai/sentiment-model-portuguese-distilbert-pos-neg | H32: TextBlob: Simplified Text Processing | I32: 9 | J32: Adjusted Rand Index (ARI), não foi a comparação pedida... | K32: =MIN((E32+I32)/2,10) -> 10 | L32: 9
A33: 21.00781-0 | B33: Carlos Augusto Freire Maia de Oliveira | C33: Carlos Augusto Freire Maia de Oliveira | D33: 9 | E33: 11 | F33: Interessante terem usado o rolling up, embora as conclusões não tenham uma justificativa adequada | G33: lucas-leme/FinBERT-PT-BR | H33: LeIA import SentimentIntensityAnalyzer | I33: 9 | J33: Adjusted Rand Index (ARI), não foi a comparação pedida... | K33: =MIN((E33+I33)/2,10) -> 10 | L33: 9.5 | M33: Apresentação muito boa, TFIDF, BERT,... Comparativos. Jogo na aplicação, muito bom. Resultados, 83% 97%. Conjunto de treinamento, talvez um pouco falho. Artigo médio e falta de referências.
A34: 21.00478-0 | B34: Cesar Fukushima Kim Bresciani | C34: Cesar Fukushima Kim Bresciani | D34: 9 | E34: 11 | F34: Interessante terem usado o rolling up, embora as conclusões não tenham uma justificativa adequada | G34: lucas-leme/FinBERT-PT-BR | H34: LeIA import SentimentIntensityAnalyzer | I34: 9 | J34: Deviam ser seguido com a matriz de confusão inicial e não o ARI | K34: =MIN((E34+I34)/2,10) -> 10 | L34: 9.5
A35: 21.01535-0 | B35: Enzo Moura | C35: Enzo Leonardo Sabatelli de Moura | D35: 9 | E35: 11 | F35: Interessante terem usado o rolling up, embora as conclusões não tenham uma justificativa adequada | G35: lucas-leme/FinBERT-PT-BR | H35: LeIA import SentimentIntensityAnalyzer | I35: 9 | J35: Deviam ser seguido com a matriz de confusão inicial e não o ARI | K35: =MIN((E35+I35)/2,10) -> 10 | L35: 9.5
A36: 21.01922-3 | B36: André Soares | C36: Andre Lucas Gois Soares | D36: 10 | E36: 9 | F36: Não chegaram na predição, mas empregaram modelos diferentes embora a análise dos dois modelos não tenha sido a mais adequada. | G36: joeddav/xlm-roberta-large-xnli | H36: from nltk.sentiment import SentimentIntensityAnalyzer | I36: 9 | J36: Adjusted Rand Index (ARI), não foi a comparação pedida... | K36: =MIN((E36+I36)/2,10) -> 9 | L36: 10 | M36: Excelente trabalho. 73%, tracking, ELO, Optuna, SHAP, empregando várias técnicas... monetizaram... A aplicação excelente, artigo também ok. Apenas o GitHub, com um trabalho tão bom, merecia uma apresentação melhor. Não encontrei lá nem o link para o vídeo (embora tenha acessado pelo link no form, e ok).
A37: 20.00041-3 | B37: Bruno Bosa Lopes | C37: Bruno Bosa Lopes | D37: 10 | E37: 9 | F37: Não chegaram na predição, mas empregaram modelos diferentes embora a análise dos dois modelos não tenha sido a mais adequada. | G37: joeddav/xlm-roberta-large-xnli | H37: from nltk.sentiment import SentimentIntensityAnalyzer | I37: 9 | J37: Adjusted Rand Index (ARI), não foi a comparação pedida... | K37: =MIN((E37+I37)/2,10) -> 9 | L37: 10
A38: 21.00931-7 | B38: Caio Montes Correia | C38: Caio Montes Correia | D38: 10 | E38: 9 | F38: Não chegaram na predição, mas empregaram modelos diferentes embora a análise dos dois modelos não tenha sido a mais adequada. | G38: joeddav/xlm-roberta-large-xnli | H38: from nltk.sentiment import SentimentIntensityAnalyzer | I38: 9 | J38: Adjusted Rand Index (ARI), não foi a comparação pedida... | K38: =MIN((E38+I38)/2,10) -> 9 | L38: 10
A39: 21.02093-0 | B39: Enzo Pucci | C39: Enzo Suannes Pucci | D39: 10 | E39: 9 | F39: Não chegaram na predição, mas empregaram modelos diferentes embora a análise dos dois modelos não tenha sido a mais adequada. | G39: joeddav/xlm-roberta-large-xnli | H39: from nltk.sentiment import SentimentIntensityAnalyzer | I39: 9 | J39: Deviam ser seguido com a matriz de confusão inicial e não o ARI | K39: =MIN((E39+I39)/2,10) -> 9 | L39: 10
A40: 21.02028-0 | B40: Pedro Mesquita | C40: Pedro Judice Mesquita | D40: 10 | E40: 9 | F40: Não chegaram na predição, mas empregaram modelos diferentes embora a análise dos dois modelos não tenha sido a mais adequada. | G40: joeddav/xlm-roberta-large-xnli | H40: from nltk.sentiment import SentimentIntensityAnalyzer | I40: 9 | J40: Adjusted Rand Index (ARI), não foi a comparação pedida... | K40: =MIN((E40+I40)/2,10) -> 9 | L40: 10

Sheet work 1
A1: RA | B1: Nome | C1: Nome | D1: Grupo | E1: Nota Ex 4.1 | F1: Comentários Ex 4.1 | G1: Modelo 1 | H1: Modelo 2 | I1: Nota Ex 4.2 | J1: Comentários Ex 4.2 | K1: Ex 4
A2: 21.01922-3 | B2: André Soares | C2: Andre Lucas Gois Soares | D2: 10 | E2: 9 | F2: Não chegaram na predição, mas empregaram modelos diferentes embora a análise dos dois modelos não tenha sido a mais adequada. | G2: joeddav/xlm-roberta-large-xnli | H2: from nltk.sentiment import SentimentIntensityAnalyzer | I2: 9 | J2: Adjusted Rand Index (ARI), não foi a comparação pedida... | K2: =MIN((E2+I2)/2,10) -> 9
A3: 21.00663-6 | B3: Antonio Macedo Ferrite | C3: Antonio Macedo Ferrite | D3: 7 | E3: 12 | F3: Excelente! | G3: !ollama pull mistral | H3: NLTK - Natural Language Toolkit | I3: 9 | J3: Adjusted Rand Index (ARI), não foi a comparação pedida... | K3: =MIN((E3+I3)/2,10) -> 10
A4: 20.02194-0 | B4: Bruno Augusto Lopes Fevereiro | C4: Bruno Augusto Lopes Fevereiro | D4: 6 | E4: 10 | F4: Análises bastante superficiais | G4: nlptown/bert-base-multilingual-uncased-sentiment | H4: LeIA import SentimentIntensityAnalyzer | I4: 9 | J4: Adjusted Rand Index (ARI), não foi a comparação pedida... | K4: =MIN((E4+I4)/2,10) -> 9.5
A5: 20.00041-3 | B5: Bruno Bosa Lopes | C5: Bruno Bosa Lopes | D5: 10 | E5: 9 | F5: Não chegaram na predição, mas empregaram modelos diferentes embora a análise dos dois modelos não tenha sido a mais adequada. | G5: joeddav/xlm-roberta-large-xnli | H5: from nltk.sentiment import SentimentIntensityAnalyzer | I5: 9 | J5: Adjusted Rand Index (ARI), não foi a comparação pedida... | K5: =MIN((E5+I5)/2,10) -> 9
A6: 21.00931-7 | B6: Caio Montes Correia | C6: Caio Montes Correia | D6: 10 | E6: 9 | F6: Não chegaram na predição, mas empregaram modelos diferentes embora a análise dos dois modelos não tenha sido a mais adequada. | G6: joeddav/xlm-roberta-large-xnli | H6: from nltk.sentiment import SentimentIntensityAnalyzer | I6: 9 | J6: Adjusted Rand Index (ARI), não foi a comparação pedida... | K6: =MIN((E6+I6)/2,10) -> 9
A7: 20.01308-6 | B7: Carlos Alberto Matias da Costa | C7: Carlos Alberto Matias da Costa | D7: 6 | E7: 10 | F7: Análises bastante superficiais | G7: nlptown/bert-base-multilingual-uncased-sentiment | H7: LeIA import SentimentIntensityAnalyzer | I7: 9 | J7: Adjusted Rand Index (ARI), não foi a comparação pedida... | K7: =MIN((E7+I7)/2,10) -> 9.5
A8: 21.00781-0 | B8: Carlos Augusto Freire Maia de Oliveira | C8: Carlos Augusto Freire Maia de Oliveira | D8: 9 | E8: 11 | F8: Interessante terem usado o rolling up, embora as conclusões não tenham uma justificativa adequada | G8: lucas-leme/FinBERT-PT-BR | H8: LeIA import SentimentIntensityAnalyzer | I8: 9 | J8: Adjusted Rand Index (ARI), não foi a comparação pedida... | K8: =MIN((E8+I8)/2,10) -> 10
